<?xml version="1.0"?>
<robot name="minipock" xmlns:xacro="http://ros.org/wiki/xacro">
  <xacro:macro name="motor"
    params="namespace:=minipock name:=motor_left x:=0.0 y:=0.0 z:=0.0
				       R:=0.0 P:=0.0 Y:=0.0 side:=1">

    <link name="${name}_base_link">
      <visual>
        <origin xyz="0 0 0.0" rpy="${pi/2} 0 0" />
        <geometry>
          <mesh filename="package://minipock_description/models/wheel_base.dae" />
        </geometry>
      </visual>
      <inertial>
        <origin xyz="0.0 -0.029 0.0" rpy="0 0 0" />
        <mass value="1.587" />
        <inertia ixx="0.014" ixy="0.0" ixz="0.0" iyy="0.025" iyz="0.0" izz="0.013" />
      </inertial>
    </link>
    <link name="${name}_wheel_link">
      <visual>
        <origin xyz="0 0 -0.024" rpy="${pi/2} 0 0" />
        <geometry>
          <mesh filename="package://minipock_description/models/wheel_rotative.dae" />
        </geometry>
      </visual>
      <collision>
        <origin xyz="0 0.032 0.0" rpy="${pi/2} -0 0" />
        <geometry>
          <cylinder radius="0.036" length="0.006" />
        </geometry>
      </collision>
      <inertial>
        <origin xyz="0.0 -0.029 0.0" rpy="0 -0 0" />
        <mass value="1.587" />
        <inertia ixx="0.014" ixy="0.0" ixz="0.0" iyy="0.025" iyz="0.0" izz="0.013" />
      </inertial>
    </link>
    <joint name="${name}_joint" type="fixed">
      <parent link="${namespace}base_link" />
      <child link="${name}_base_link" />
      <origin xyz="${x} ${y} ${z}" rpy="${R} ${P} ${Y}" />
    </joint>
    <joint name="${name}_wheel_joint" type="continuous">
      <parent link="${name}_base_link" />
      <child link="${name}_wheel_link" />
      <origin xyz="0.0 0.0 0.024" rpy="0 0 0" />
      <axis xyz="0 ${side} 0" />
      <limit effort="2000" velocity="45.5"/>
    </joint>
    <gazebo>
      <plugin filename="gz-sim-joint-controller-system"
        name="gz::sim::systems::JointController">
        <joint_name>${name}_wheel_joint</joint_name>
        <use_velocity_commands>true</use_velocity_commands>
        <topic>${namespace}${name}/pos</topic>
        <name>${name}</name>
      </plugin>
    </gazebo>
  </xacro:macro>
</robot>