<?xml version="1.0"?>
<robot name="minipock" xmlns:xacro="http://ros.org/wiki/xacro">
  <xacro:macro name="motor"
    params="namespace:=minipock name:=motor_left x:=0.0 y:=0.0 z:=0.0
				       R:=0.0 P:=0.0 Y:=0.0 side:=1 mode:='differential'">

    <link name="${name}_base_link">
      <visual>
        <origin xyz="0 0 0.0" rpy="${pi/2} 0 0" />
        <geometry>
          <mesh filename="package://minipock_description/models/wheel_base.dae" />
        </geometry>
      </visual>
      <inertial>
        <origin xyz="0.0 -0.029 0.0" rpy="0 0 0" />
        <mass value="1.587" />
        <inertia ixx="0.014" ixy="0.0" ixz="0.0" iyy="0.025" iyz="0.0" izz="0.013" />
      </inertial>
    </link>


    <xacro:if value="${mode == 'differential'}">
      <link name="${name}_wheel_link">
        <visual>
          <origin xyz="0 0 -0.024" rpy="${pi/2} 0 0" />
          <geometry>
            <mesh filename="package://minipock_description/models/wheel_rotative.dae" />
          </geometry>
        </visual>
        <collision>
          <origin xyz="0 0.032 0.0" rpy="${pi/2} -0 0" />
          <geometry>
            <cylinder radius="0.036" length="0.006" />
          </geometry>
        </collision>
        <inertial>
          <origin xyz="0.0 -0.029 0.0" rpy="0 -0 0" />
          <mass value="1.587" />
          <inertia ixx="0.014" ixy="0.0" ixz="0.0" iyy="0.025" iyz="0.0" izz="0.013" />
        </inertial>
      </link>
      <joint name="${name}_wheel_joint" type="continuous">
        <parent link="${name}_base_link" />
        <child link="${name}_wheel_link" />
        <origin xyz="0.0 0.0 0.024" rpy="0 0 0" />
        <axis xyz="0 ${side} 0" />
        <limit effort="2000" velocity="45.5" />
      </joint>
    </xacro:if>

    <xacro:if value="${mode == 'holonomic'}">
      <link name="${name}_wheel_link">
        <visual>
          <origin xyz="-4.8572257327350598644e-17 0 -0.0099999999999999793915"
            rpy="1.570796326794896558 -0 -3.8098343924097847915e-13" />
          <geometry>
            <mesh filename="package://minipock_description/models/wheel_core.stl" />
          </geometry>
          <material name="${name}_wheel_link_material">
            <color
              rgba="0.06862745098039220171 0.08627450980392152857 0.05294117647058818044 1.0" />
          </material>
        </visual>
        <inertial>
          <origin
            xyz="-7.1267906557384964552e-06 -7.4554367595184111139e-06 -0.0074565222160878352753"
            rpy="0 0 0" />
          <mass value="0.0084406729050052354407" />
          <inertia ixx="1.6585465159980563238e-06" ixy="8.7787669783305516839e-10"
            ixz="-1.4548784474885956158e-10" iyy="1.6586259130583059041e-06"
            iyz="-1.5219483721075413049e-10" izz="3.2828932950195218582e-06" />
        </inertial>
      </link>
      <joint name="${name}_wheel_joint" type="continuous">
        <parent link="${name}_base_link" />
        <child link="${name}_wheel_link" />
        <origin xyz="0.0 0.02 0.024" rpy="${pi/2} 0 0" />
        <axis xyz="0 0 ${side}" />
        <limit effort="2000" velocity="45.5" />
      </joint>

      <link name="${name}_roller">
        <visual>
          <origin xyz="0 3.4694469519536141888e-18 -0.0080000000000000019013"
            rpy="6.8813454446235181599e-18 8.8647375544077344568e-32 -4.6879817938295213445e-32" />
          <geometry>
            <mesh filename="package://minipock_description/models/roller.stl" />
          </geometry>
          <material name="roller_material">
            <color
              rgba="0.14705882352941179736 0.14705882352941179736 0.14705882352941179736 1.0" />
          </material>
        </visual>
        <collision>
          <origin xyz="0 3.4694469519536141888e-18 -0.0080000000000000019013"
            rpy="6.8813454446235181599e-18 8.8647375544077344568e-32 -4.6879817938295213445e-32" />
          <geometry>
            <cylinder radius="0.006" length="0.016" />
          </geometry>
        </collision>
        <inertial>
          <origin
            xyz="4.0653990009220675453e-20 3.4694469519536141888e-18 -0.0079999999999998301636"
            rpy="0 0 0" />
          <mass value="0.0015147722925255755443" />
          <inertia ixx="4.0501606036357593342e-08" ixy="-3.797415834386005416e-39"
            ixz="-6.0354810964727493848e-39" iyy="4.0501606036357580107e-08"
            iyz="2.5452931631559141688e-25" izz="2.7582542641815001703e-08" />
        </inertial>
      </link>

      <joint name="${name}_joint_roller_6_continuous" type="continuous">
        <origin xyz="-0.028131604665040808172 0.013220856400772910966 -0.0049999999999999905631"
          rpy="-1.3962634015950849964 1.5707963267948952257 0" />
        <parent link="${name}_wheel_link" />
        <child link="${name}_roller" />
        <axis xyz="0 0 1" />
        <limit effort="1" velocity="20" />

      </joint>

      <link name="${name}_roller_2">
        <visual>
          <origin xyz="0 0 -0.0080000000000000001665"
            rpy="3.344220525918795236e-17 7.1776823159320073863e-32 -4.3756900247071136203e-32" />
          <geometry>
            <mesh filename="package://minipock_description/models/roller.stl" />
          </geometry>
          <material name="roller_material">
            <color
              rgba="0.14705882352941179736 0.14705882352941179736 0.14705882352941179736 1.0" />
          </material>
        </visual>
        <collision>
          <origin xyz="0 0 -0.0080000000000000001665"
            rpy="3.344220525918795236e-17 7.1776823159320073863e-32 -4.3756900247071136203e-32" />
          <geometry>
            <cylinder radius="0.006" length="0.016" />
          </geometry>
        </collision>
        <inertial>
          <origin
            xyz="4.0653990009220675453e-20 -7.7117331372288384241e-33 -0.0079999999999998284289"
            rpy="0 0 0" />
          <mass value="0.0015147722925255755443" />
          <inertia ixx="4.0501606036357593342e-08" ixy="-3.5444494703583487718e-39"
            ixz="-2.8469773786836133355e-39" iyy="4.0501606036357593342e-08"
            iyz="1.156163772428913307e-25" izz="2.7582542641815001703e-08" />
        </inertial>
      </link>

      <joint name="${name}_joint_roller_5_continuous" type="continuous">
        <origin xyz="-0.030048262113536068629 -0.0079548833402023552686 -0.0049999999999999801548"
          rpy="-2.0943951023928160105 1.5707963267948950037 0" />
        <parent link="${name}_wheel_link" />
        <child link="${name}_roller_2" />
        <axis xyz="0 0 1" />
        <limit effort="1" velocity="20" />

      </joint>

      <link name="${name}_roller_3">
        <visual>
          <origin xyz="0 -6.9388939039072283776e-18 -0.008000000000000003636"
            rpy="4.1764705181552599466e-17 -3.5419409732648655226e-32 -4.9611279807583270422e-32" />
          <geometry>
            <mesh filename="package://minipock_description/models/roller.stl" />
          </geometry>
          <material name="roller_material">
            <color
              rgba="0.14705882352941179736 0.14705882352941179736 0.14705882352941179736 1.0" />
          </material>
        </visual>
        <collision>
          <origin xyz="0 -6.9388939039072283776e-18 -0.008000000000000003636"
            rpy="4.1764705181552599466e-17 -3.5419409732648655226e-32 -4.9611279807583270422e-32" />
          <geometry>
            <cylinder radius="0.006" length="0.016" />
          </geometry>
        </collision>
        <inertial>
          <origin
            xyz="4.0653990009220675453e-20 -6.9388939039072175924e-18 -0.0079999999999998318984"
            rpy="0 0 0" />
          <mass value="0.0015147722925255755443" />
          <inertia ixx="4.0501606036357593342e-08" ixy="-4.0186730194524519184e-39"
            ixz="3.0914625319782431716e-39" iyy="4.0501606036357580107e-08"
            iyz="3.4848619352074722379e-24" izz="2.7582542641815001703e-08" />
        </inertial>
      </link>

      <joint name="${name}_joint_roller_4_continuous" type="continuous">
        <origin xyz="-0.017905003769872984004 -0.025408444757616242826 -0.0049999999999999775527"
          rpy="-2.7925268031905519095 1.5707963267948958919 0" />
        <parent link="${name}_wheel_link" />
        <child link="${name}_roller_3" />
        <axis xyz="0 0 1" />
        <limit effort="1" velocity="20" />

      </joint>

      <link name="${name}_roller_4">
        <visual>
          <origin xyz="0 3.4694469519536141888e-18 -0.0079999999999999984318"
            rpy="1.8300819703905588982e-17 -5.734781960728272461e-32 -4.8576291355316246858e-32" />
          <geometry>
            <mesh filename="package://minipock_description/models/roller.stl" />
          </geometry>
          <material name="roller_material">
            <color
              rgba="0.14705882352941179736 0.14705882352941179736 0.14705882352941179736 1.0" />
          </material>
        </visual>
        <collision>
          <origin xyz="0 3.4694469519536141888e-18 -0.0079999999999999984318"
            rpy="1.8300819703905588982e-17 -5.734781960728272461e-32 -4.8576291355316246858e-32" />
          <geometry>
            <cylinder radius="0.006" length="0.016" />
          </geometry>
        </collision>
        <inertial>
          <origin
            xyz="4.0653990009220675453e-20 3.4694469519536180407e-18 -0.0079999999999998266942"
            rpy="0 0 0" />
          <mass value="0.0015147722925255755443" />
          <inertia ixx="4.0501606036357593342e-08" ixy="-3.4356147928490457005e-39"
            ixz="1.1846287819213605257e-39" iyy="4.0501606036357593342e-08"
            iyz="1.386434340951947943e-24" izz="2.7582542641814995085e-08" />
        </inertial>
      </link>

      <joint name="${name}_joint_roller_3_continuous" type="continuous">
        <origin xyz="0.0026162048296650758025 -0.030973112489532557412 -0.0049999999999999723485"
          rpy="2.7925268031913015321 1.5707963267948958919 0" />
        <parent link="${name}_wheel_link" />
        <child link="${name}_roller_4" />
        <axis xyz="0 0 1" />
        <limit effort="1" velocity="20" />

      </joint>

      <link name="${name}_roller_5">
        <visual>
          <origin xyz="0 0 -0.0080000000000000001665"
            rpy="2.2839705893320894994e-17 -2.864306808693828181e-32 -3.5002571411063758511e-32" />
          <geometry>
            <mesh filename="package://minipock_description/models/roller.stl" />
          </geometry>
          <material name="roller_material">
            <color
              rgba="0.14705882352941179736 0.14705882352941179736 0.14705882352941179736 1.0" />
          </material>
        </visual>
        <collision>
          <origin xyz="0 0 -0.0080000000000000001665"
            rpy="2.2839705893320894994e-17 -2.864306808693828181e-32 -3.5002571411063758511e-32" />
          <geometry>
            <cylinder radius="0.006" length="0.016" />
          </geometry>
        </collision>
        <inertial>
          <origin
            xyz="4.0653990009220675453e-20 1.8368986437516643564e-32 -0.0079999999999998284289"
            rpy="0 0 0" />
          <mass value="0.0015147722925255755443" />
          <inertia ixx="4.0501606036357593342e-08" ixy="-1.8368790400774327246e-39"
            ixz="1.950138906230126744e-39" iyy="4.0501606036357593342e-08"
            iyz="3.8772395094805603405e-24" izz="2.7582542641815001703e-08" />
        </inertial>
      </link>

      <joint name="${name}_joint_roller_2_continuous" type="continuous">
        <origin xyz="0.021913262113524886732 -0.022045116659794552344 -0.0049999999999999723485"
          rpy="2.0943951023935678535 1.5707963267948958919 0" />
        <parent link="${name}_wheel_link" />
        <child link="${name}_roller_5" />
        <axis xyz="0 0 1" />
        <limit effort="1" velocity="20" />

      </joint>

      <link name="${name}_roller_6">
        <visual>
          <origin xyz="0 0 -0.0080000000000000019013"
            rpy="2.0225207513426638564e-17 1.2168204653565115077e-32 -4.7592279802773546759e-32" />
          <geometry>
            <mesh filename="package://minipock_description/models/roller.stl" />
          </geometry>
          <material name="roller_material">
            <color
              rgba="0.14705882352941179736 0.14705882352941179736 0.14705882352941179736 1.0" />
          </material>
        </visual>
        <collision>
          <origin xyz="0 0 -0.0080000000000000019013"
            rpy="2.0225207513426638564e-17 1.2168204653565115077e-32 -4.7592279802773546759e-32" />
          <geometry>
            <cylinder radius="0.006" length="0.016" />
          </geometry>
        </collision>
        <inertial>
          <origin
            xyz="4.0653990009220675453e-20 -4.2240899565863731609e-33 -0.0079999999999998301636"
            rpy="0 0 0" />
          <mass value="0.0015147722925255755443" />
          <inertia ixx="4.0501606036357593342e-08" ixy="4.1324058662983676952e-39"
            ixz="5.3146249251520744987e-40" iyy="4.0501606036357580107e-08"
            iyz="1.4075358286583683246e-25" izz="2.7582542641815001703e-08" />
        </inertial>
      </link>

      <joint name="${name}_joint_roller_1_continuous" type="continuous">
        <origin xyz="0.030956860515685625385 -0.002801965740757847434 -0.0049999999999999801548"
          rpy="1.3962634015958343969 1.5707963267948956698 0" />
        <parent link="${name}_wheel_link" />
        <child link="${name}_roller_6" />
        <axis xyz="0 0 1" />
        <limit effort="1" velocity="20" />

      </joint>

      <link name="${name}_roller_7">
        <visual>
          <origin
            xyz="-8.6736173798840354721e-19 -3.4694469519536141888e-18 -0.0080000000000000019013"
            rpy="3.5000374571518725879e-17 9.9907289254227972128e-32 -4.5256152872817977519e-32" />
          <geometry>
            <mesh filename="package://minipock_description/models/roller.stl" />
          </geometry>
          <material name="roller_material">
            <color
              rgba="0.14705882352941179736 0.14705882352941179736 0.14705882352941179736 1.0" />
          </material>
        </visual>
        <collision>
          <origin
            xyz="-8.6736173798840354721e-19 -3.4694469519536141888e-18 -0.0080000000000000019013"
            rpy="3.5000374571518725879e-17 9.9907289254227972128e-32 -4.5256152872817977519e-32" />
          <geometry>
            <cylinder radius="0.006" length="0.016" />
          </geometry>
        </collision>
        <inertial>
          <origin
            xyz="-8.2670774797918282962e-19 -3.4694469519535903073e-18 -0.0079999999999998301636"
            rpy="0 0 0" />
          <mass value="0.0015147722925255755443" />
          <inertia ixx="4.0501606036357593342e-08" ixy="-5.6627770987987060653e-39"
            ixz="-6.8021027356180279832e-39" iyy="4.0501606036357580107e-08"
            iyz="5.2616856038168206013e-24" izz="2.7582542641815001703e-08" />
        </inertial>
      </link>

      <joint name="${name}_joint_roller_9_continuous" type="continuous">
        <origin xyz="0.025515399835375589255 0.017752256088759903185 -0.004999999999999987961"
          rpy="0.69813170079810316082 1.5707963267948954478 0" />
        <parent link="${name}_wheel_link" />
        <child link="${name}_roller_7" />
        <axis xyz="0 0 1" />
        <limit effort="1" velocity="20" />

      </joint>

      <link name="${name}_roller_8">
        <visual>
          <origin xyz="0 0 -0.0080000000000000001665"
            rpy="-1.621467491797687631e-29 1.8610995229314101184e-46 4.0931594027710871881e-58" />
          <geometry>
            <mesh filename="package://minipock_description/models/roller.stl" />
          </geometry>
          <material name="roller_material">
            <color
              rgba="0.14705882352941179736 0.14705882352941179736 0.14705882352941179736 1.0" />
          </material>
        </visual>
        <collision>
          <origin xyz="0 0 -0.0080000000000000001665"
            rpy="-1.621467491797687631e-29 1.8610995229314101184e-46 4.0931594027710871881e-58" />
          <geometry>
            <cylinder radius="0.006" length="0.016" />
          </geometry>
        </collision>
        <inertial>
          <origin
            xyz="4.0653990009220675453e-20 -2.4291758313930170346e-36 -0.0079999999999998284289"
            rpy="0 0 0" />
          <mass value="0.0015147722925255755443" />
          <inertia ixx="4.0501606036357593342e-08" ixy="3.3155905915009507884e-65"
            ixz="-1.2671137662413786051e-53" iyy="4.0501606036357593342e-08"
            iyz="-2.0947841318724297231e-37" izz="2.7582542641815001703e-08" />
        </inertial>
      </link>

      <joint name="${name}_joint_roller_8_continuous" type="continuous">
        <origin xyz="0.0081350000000113779214 0.029999999999996886796 -0.0049999999999999792874"
          rpy="3.8172294696792983199e-13 1.570796326794896558 0" />
        <parent link="${name}_wheel_link" />
        <child link="${name}_roller_8" />
        <axis xyz="0 0 1" />
        <limit effort="1" velocity="20" />

      </joint>
      <link name="${name}_roller_9">
        <visual>
          <origin xyz="0 0 -0.0080000000000000001665"
            rpy="6.7221822527689735584e-18 -8.7180519648836596984e-33 -1.2569312029751666415e-31" />
          <geometry>
            <mesh filename="package://minipock_description/models/roller.stl" />
          </geometry>
          <material name="roller_material">
            <color
              rgba="0.14705882352941179736 0.14705882352941179736 0.14705882352941179736 1.0" />
          </material>
        </visual>
        <collision>
          <origin xyz="0 0 -0.0080000000000000001665"
            rpy="6.7221822527689735584e-18 -8.7180519648836596984e-33 -1.2569312029751666415e-31" />
          <geometry>
            <mesh filename="package://minipock_description/models/roller.stl" />
          </geometry>
        </collision>
        <inertial>
          <origin
            xyz="4.0653990009220675453e-20 2.3540384680750280962e-32 -0.0079999999999998284289"
            rpy="0 0 0" />
          <mass value="0.0015147722925255755443" />
          <inertia ixx="4.0501606036357593342e-08" ixy="-4.6621608404600178297e-39"
            ixz="-6.5460416771372355481e-39" iyy="4.0501606036357593342e-08"
            iyz="4.055471787642257058e-24" izz="2.7582542641814991776e-08" />
        </inertial>
      </link>

      <joint name="${name}_joint_roller_7_continuous" type="continuous">
        <origin xyz="-0.013258688745465072728 0.028036857843754141306 -0.0049999999999999992367"
          rpy="-0.69813170079771968979 1.5707963267948958919 0" />
        <parent link="${name}_wheel_link" />
        <child link="${name}_roller_9" />
        <axis xyz="0 0 1" />
        <limit effort="1" velocity="20" />
        <joint_properties friction="0.0" />
      </joint>
    </xacro:if>


    <joint name="${name}_joint" type="fixed">
      <parent link="${namespace}base_link" />
      <child link="${name}_base_link" />
      <origin xyz="${x} ${y} ${z}" rpy="${R} ${P} ${Y}" />
    </joint>


    <gazebo>
      <plugin filename="gz-sim-joint-controller-system"
        name="gz::sim::systems::JointController">
        <joint_name>${name}_wheel_joint</joint_name>
        <use_velocity_commands>true</use_velocity_commands>
        <topic>${namespace}${name}/pos</topic>
        <name>${name}</name>
      </plugin>
    </gazebo>
  </xacro:macro>
</robot>
